Traceback (most recent call last):
  File "/root/github/study/python/chapter10/./main.py", line 7, in <module>
    raise Exception('Error: test error.');
Exception: Error: test error.
